Workbook

Sheet Assumptions
A1: Ágio — Financial Model
A2: Assumptions and input variables — adjust the blue cells to simulate scenarios
A4: PRICING AND UNIT ECONOMICS
A5: Fee charged to the worker | B5: 9.9
A6: % Commission to firm | B6: 0.25
A7: Commission paid to firm | B7: =B5*B6 -> 2.475
A8: Net Ágio revenue per transaction | B8: =B5-B7 -> 7.425
A9: Cost of capital (FIDC) per transaction | B9: 2.46
A10: Pix cost per transaction | B10: 1
A11: Allocated backend/cloud cost | B11: 0.4
A12: KYC/antifraud cost | B12: 0.3
A13: Allocated support cost | B13: 0.5
A14: Total direct cost per transaction | B14: =SUM(B9:B13) -> 4.66
A15: Gross margin per transaction | B15: =B8-B14 -> 2.765
A18: OPERATIONAL ASSUMPTIONS
A19: Advance frequency per active user/month | B19: 1.5
A20: Average ticket per advance | B20: 200
A21: Total employees per firm (average) | B21: 1500
A22: Activation rate at steady state (after 6 months) | B22: 0.3
A23: Activation rate in 1st month of operation | B23: 0.05
A26: FIRM ACQUISITION CURVE (12 months)
A27: Month | B27: Active firms | C27: Note
A28: Month 1 | B28: 0 | C28: Technical validation
A29: Month 2 | B29: 0 | C29: First conversations
A30: Month 3 | B30: 1 | C30: First pilot
A31: Month 4 | B31: 1 | C31: Refinement
A32: Month 5 | B32: 2 | C32: Second firm
A33: Month 6 | B33: 3 | C33: Acceleration
A34: Month 7 | B34: 4
A35: Month 8 | B35: 5
A36: Month 9 | B36: 6
A37: Month 10 | B37: 7
A38: Month 11 | B38: 8
A39: Month 12 | B39: 9 | C39: Near break-even
A42: MONTHLY FIXED COSTS
A43: Phase | B43: Months | C43: Monthly cost (R$) | D43: Composition
A44: Validation | B44: 1-3 | C44: 200 | D44: Claude Pro Max + hosting (Lucas solo)
A45: First firms | B45: 4-6 | C45: 9500 | D45: Dev R$6k + contractor support R$2.5k + infra/SW R$1k
A46: Expansion | B46: 7-12 | C46: 18500 | D46: Dev R$7k + support R$3k + CS R$4k + mkt R$2k + legal R$1.5k + infra R$1k
A49: INVESTMENT AND ANALYSIS
...

Sheet Projection_12M
A1: Monthly projection — 12 months
A2: Revenue, costs, EBITDA and cash flow month by month
A4: Indicator | B4: Month 1 | C4: Month 2 | D4: Month 3 | E4: Month 4 | F4: Month 5 | G4: Month 6 | H4: Month 7 | I4: Month 8 | J4: Month 9 | K4: Month 10 | L4: Month 11 | M4: Month 12 | N4: Year 1 Total
A5: OPERATIONAL
A6: Active firms (end of month) | B6: =Assumptions!B28 -> 0 | C6: =Assumptions!B29 -> 0 | D6: =Assumptions!B30 -> 1 | E6: =Assumptions!B31 -> 1 | F6: =Assumptions!B32 -> 2 | G6: =Assumptions!B33 -> 3 | H6: =Assumptions!B34 -> 4 | I6: =Assumptions!B35 -> 5 | J6: =Assumptions!B36 -> 6 | K6: =Assumptions!B37 -> 7 | L6: =Assumptions!B38 -> 8 | M6: =Assumptions!B39 -> 9 | N6: =M6 -> 9
A7: Total employees in portfolio | B7: =B6*Assumptions!B21 -> 0 | C7: =C6*Assumptions!B21 -> 0 | D7: =D6*Assumptions!B21 -> 1500 | E7: =E6*Assumptions!B21 -> 1500 | F7: =F6*Assumptions!B21 -> 3000 | G7: =G6*Assumptions!B21 -> 4500 | H7: =H6*Assumptions!B21 -> 6000 | I7: =I6*Assumptions!B21 -> 7500 | J7: =J6*Assumptions!B21 -> 9000 | K7: =K6*Assumptions!B21 -> 10500 | L7: =L6*Assumptions!B21 -> 12000 | M7: =M6*Assumptions!B21 -> 13500 | N7: =M7 -> 13500
A8: Average activation rate | B8: 0 | C8: 0 | D8: =MIN(Assumptions!B22,Assumptions!B23+0.05*1) -> 0.1 | E8: =MIN(Assumptions!B22,Assumptions!B23+0.05*2) -> 0.15 | F8: =MIN(Assumptions!B22,Assumptions!B23+0.05*3) -> 0.2 | G8: =MIN(Assumptions!B22,Assumptions!B23+0.05*4) -> 0.25 | H8: =MIN(Assumptions!B22,Assumptions!B23+0.05*5) -> 0.3 | I8: =MIN(Assumptions!B22,Assumptions!B23+0.05*6) -> 0.3 | J8: =MIN(Assumptions!B22,Assumptions!B23+0.05*7) -> 0.3 | K8: =MIN(Assumptions!B22,Assumptions!B23+0.05*8) -> 0.3 | L8: =MIN(Assumptions!B22,Assumptions!B23+0.05*9) -> 0.3 | M8: =MIN(Assumptions!B22,Assumptions!B23+0.05*10) -> 0.3 | N8: =M8 -> 0.3
A9: Active users | B9: =ROUND(B7*B8,0) -> 0 | C9: =ROUND(C7*C8,0) -> 0 | D9: =ROUND(D7*D8,0) -> 150 | E9: =ROUND(E7*E8,0) -> 225 | F9: =ROUND(F7*F8,0) -> 600 | G9: =ROUND(G7*G8,0) -> 1125 | H9: =ROUND(H7*H8,0) -> 1800 | I9: =ROUND(I7*I8,0) -> 2250 | ... M9: =ROUND(M7*M8,0) -> 4050 | N9: =M9 -> 4050
A10: Advances in the month | B10: =ROUND(B9*Assumptions!B19,0) -> 0 | C10: =ROUND(C9*Assumptions!B19,0) -> 0 | D10: =ROUND(D9*Assumptions!B19,0) -> 225 | E10: =ROUND(E9*Assumptions!B19,0) -> 338 | F10: =ROUND(F9*Assumptions!B19,0) -> 900 | G10: =ROUND(G9*Assumptions!B19,0) -> 1688 | H10: =ROUND(H9*Assumptions!B19,0) -> 2700 | I10: =ROUND(I9*Assumptions!B19,0) -> 3375 | J10: =ROUND(J9*Assumptions!B19,0) -> 4050 | K10: =ROUND(K9*Assumptions!B19,0) -> 4725 | L10: =ROUND(L9*Assumptions!B19,0) -> 5400 | M10: =ROUND(M9*Assumptions!B19,0) -> 6075 | N10: =SUM(B10:M10) -> 29476
A12: REVENUE
A13: Gross revenue (total fee) | B13: =B10*Assumptions!B5 -> 0 | C13: =C10*Assumptions!B5 -> 0 | D13: =D10*Assumptions!B5 -> 2227.5 | E13: =E10*Assumptions!B5 -> 3346.2 | F13: =F10*Assumptions!B5 -> 8910 | G13: =G10*Assumptions!B5 -> 16711.2 | H13: =H10*Assumptions!B5 -> 26730 | I13: =I10*Assumptions!B5 -> 33412.5 | J13: =J10*Assumptions!B5 -> 40095 | K13: =K10*Assumptions!B5 -> 46777.5 | L13: =L10*Assumptions!B5 -> 53460 | M13: =M10*Assumptions!B5 -> 60142.5 | N13: =SUM(B13:M13) -> 291812.4
A14: (-) Commission paid to firm | B14: =-B10*Assumptions!B7 -> 0 | C14: =-C10*Assumptions!B7 -> 0 | D14: =-D10*Assumptions!B7 -> -556.875 | E14: =-E10*Assumptions!B7 -> -836.55 | F14: =-F10*Assumptions!B7 -> -2227.5 | G14: =-G10*Assumptions!B7 -> -4177.8 | H14: =-H10*Assumptions!B7 -> -6682.5 | I14: =-I10*Assumptions!B7 -> -8353.125 | J14: =-J10*Assumptions!B7 -> -10023.75 | K14: =-K10*Assumptions!B7 -> -11694.375 | L14: =-L10*Assumptions!B7 -> -13365 | M14: =-M10*Assumptions!B7 -> -15035.625 | N14: =SUM(B14:M14) -> -72953.1
A15: Net revenue | B15: =B13+B14 -> 0 | C15: =C13+C14 -> 0 | D15: =D13+D14 -> 1670.625 | E15: =E13+E14 -> 2509.65 | F15: =F13+F14 -> 6682.5 | G15: =G13+G14 -> 12533.4 | H15: =H13+H14 -> 20047.5 | I15: =I13+I14 -> 25059.375 | ... M15: =M13+M14 -> 45106.875 | N15: =SUM(B15:M15) -> 218859.3
A17: DIRECT COSTS (VARIABLE)
A18: (-) Cost of capital (FIDC) | B18: =-B10*Assumptions!B9 -> 0 | C18: =-C10*Assumptions!B9 -> 0 | D18: =-D10*Assumptions!B9 -> -553.5 | E18: =-E10*Assumptions!B9 -> -831.48 | F18: =-F10*Assumptions!B9 -> -2214 | G18: =-G10*Assumptions!B9 -> -4152.48 | H18: =-H10*Assumptions!B9 -> -6642 | I18: =-I10*Assumptions!B9 -> -8302.5 | J18: =-J10*Assumptions!B9 -> -9963 | K18: =-K10*Assumptions!B9 -> -11623.5 | L18: =-L10*Assumptions!B9 -> -13284 | M18: =-M10*Assumptions!B9 -> -14944.5 | N18: =SUM(B18:M18) -> -72510.96
A19: (-) Pix cost | B19: =-B10*Assumptions!B10 -> 0 | C19: =-C10*Assumptions!B10 -> 0 | D19: =-D10*Assumptions!B10 -> -225 | E19: =-E10*Assumptions!B10 -> -338 | F19: =-F10*Assumptions!B10 -> -900 | G19: =-G10*Assumptions!B10 -> -1688 | H19: =-H10*Assumptions!B10 -> -2700 | I19: =-I10*Assumptions!B10 -> -3375 | J19: =-J10*Assumptions!B10 -> -4050 | K19: =-K10*Assumptions!B10 -> -4725 | L19: =-L10*Assumptions!B10 -> -5400 | M19: =-M10*Assumptions!B10 -> -6075 | N19: =SUM(B19:M19) -> -29476
A20: (-) Backend/cloud cost | B20: =-B10*Assumptions!B11 -> 0 | C20: =-C10*Assumptions!B11 -> 0 | D20: =-D10*Assumptions!B11 -> -90 | E20: =-E10*Assumptions!B11 -> -135.2 | F20: =-F10*Assumptions!B11 -> -360 | G20: =-G10*Assumptions!B11 -> -675.2 | H20: =-H10*Assumptions!B11 -> -1080 | I20: =-I10*Assumptions!B11 -> -1350 | J20: =-J10*Assumptions!B11 -> -1620 | K20: =-K10*Assumptions!B11 -> -1890 | L20: =-L10*Assumptions!B11 -> -2160 | M20: =-M10*Assumptions!B11 -> -2430 | N20: =SUM(B20:M20) -> -11790.4
A21: (-) KYC/antifraud cost | B21: =-B10*Assumptions!B12 -> 0 | C21: =-C10*Assumptions!B12 -> 0 | D21: =-D10*Assumptions!B12 -> -67.5 | E21: =-E10*Assumptions!B12 -> -101.4 | F21: =-F10*Assumptions!B12 -> -270 | G21: =-G10*Assumptions!B12 -> -506.4 | H21: =-H10*Assumptions!B12 -> -810 | I21: =-I10*Assumptions!B12 -> -1012.5 | J21: =-J10*Assumptions!B12 -> -1215 | K21: =-K10*Assumptions!B12 -> -1417.5 | L21: =-L10*Assumptions!B12 -> -1620 | M21: =-M10*Assumptions!B12 -> -1822.5 | N21: =SUM(B21:M21) -> -8842.8
A22: (-) Allocated support cost | B22: =-B10*Assumptions!B13 -> 0 | C22: =-C10*Assumptions!B13 -> 0 | D22: =-D10*Assumptions!B13 -> -112.5 | E22: =-E10*Assumptions!B13 -> -169 | F22: =-F10*Assumptions!B13 -> -450 | G22: =-G10*Assumptions!B13 -> -844 | H22: =-H10*Assumptions!B13 -> -1350 | I22: =-I10*Assumptions!B13 -> -1687.5 | J22: =-J10*Assumptions!B13 -> -2025 | K22: =-K10*Assumptions!B13 -> -2362.5 | L22: =-L10*Assumptions!B13 -> -2700 | M22: =-M10*Assumptions!B13 -> -3037.5 | N22: =SUM(B22:M22) -> -14738
A23: Total direct costs | B23: =SUM(B18:B22) -> 0 | C23: =SUM(C18:C22) -> 0 | D23: =SUM(D18:D22) -> -1048.5 | E23: =SUM(E18:E22) -> -1575.08 | F23: =SUM(F18:F22) -> -4194 | G23: =SUM(G18:G22) -> -7866.08 | H23: =SUM(H18:H22) -> -12582 | I23: =SUM(I18:I22) -> -15727.5 | ... M23: =SUM(M18:M22) -> -28309.5 | N23: =SUM(B23:M23) -> -137358.16
A24: GROSS MARGIN | B24: =B15+B23 -> 0 | C24: =C15+C23 -> 0 | D24: =D15+D23 -> 622.125 | E24: =E15+E23 -> 934.57 | F24: =F15+F23 -> 2488.5 | G24: =G15+G23 -> 4667.32 | H24: =H15+H23 -> 7465.5 | I24: =I15+I23 -> 9331.875 | ... M24: =M15+M23 -> 16797.375 | N24: =SUM(B24:M24) -> 81501.14
A26: FIXED COSTS
A27: (-) Monthly fixed costs | B27: =-Assumptions!C44 -> -200 | C27: =-Assumptions!C44 -> -200 | D27: =-Assumptions!C44 -> -200 | E27: =-Assumptions!C45 -> -9500 | F27: =-Assumptions!C45 -> -9500 | G27: =-Assumptions!C45 -> -9500 | H27: =-Assumptions!C46 -> -18500 | I27: =-Assumptions!C46 -> -18500 | J27: =-Assumptions!C46 -> -18500 | K27: =-Assumptions!C46 -> -18500 | L27: =-Assumptions!C46 -> -18500 | M27: =-Assumptions!C46 -> -18500 | N27: =SUM(B27:M27) -> -140100
A29: EBITDA | B29: =B24+B27 -> -200 | C29: =C24+C27 -> -200 | D29: =D24+D27 -> 422.125 | E29: =E24+E27 -> -8565.43 | F29: =F24+F27 -> -7011.5 | G29: =G24+G27 -> -4832.68 | H29: =H24+H27 -> -11034.5 | I29: =I24+I27 -> -9168.125 | ... M29: =M24+M27 -> -1702.625 | N29: =SUM(B29:M29) -> -58598.86
A30: EBITDA margin (on net revenue) | B30: =IFERROR(B29/B15,0) -> 0 | C30: =IFERROR(C29/C15,0) -> 0 | D30: =IFERROR(D29/D15,0) -> 0.2526749 | E30: =IFERROR(E29/E15,0) -> -3.4129978 | F30: =IFERROR(F29/F15,0) -> -1.0492331 | G30: =IFERROR(G29/G15,0) -> -0.38558412 | H30: =IFERROR(H29/H15,0) -> -0.55041776 | I30: =IFERROR(I29/I15,0) -> -0.36585609 | ... N30: =IFERROR(N29/N15,0) -> -0.26774672
A32: CASH FLOW
A33: Capital contributions | B33: =Assumptions!B50 -> 3000 | C33: 0 | D33: =Assumptions!B51 -> 100000 | E33: 0 | F33: 0 | G33: 0 | H33: 0 | I33: 0 | J33: 0 | K33: 0 | L33: 0 | M33: 0 | N33: =SUM(B33:M33) -> 103000
A34: Cash flow of the month | B34: =B29+B33 -> 2800 | C34: =C29+C33 -> -200 | D34: =D29+D33 -> 100422.12 | E34: =E29+E33 -> -8565.43 | F34: =F29+F33 -> -7011.5 | G34: =G29+G33 -> -4832.68 | H34: =H29+H33 -> -11034.5 | I34: =I29+I33 -> -9168.125 | ... M34: =M29+M33 -> -1702.625
A35: Accumulated cash | B35: =B34 -> 2800 | C35: =B35+C34 -> 2600 | D35: =C35+D34 -> 103022.12 | E35: =D35+E34 -> 94456.695 | F35: =E35+F34 -> 87445.195 | G35: =F35+G34 -> 82612.515 | H35: =G35+H34 -> 71578.015 | I35: =H35+I34 -> 62409.89 | J35: =I35+J34 -> 55108.14 | ... M35: =L35+M34 -> 44401.14

Sheet Projection_36M
A1: Extended projection — 36 months
A2: Year 1 detailed + projection of years 2 and 3 (stabilized growth)
A4: Indicator | B4: Year 1 | C4: Year 2 | D4: Year 3 | E4: Assumption
A6: Growth of active firms | B6: =Projection_12M!N6 -> 9 | C6: 20 | D6: 35 | E6: Progressive growth to 35 firms in year 3
A7: Average active users in the year | B7: =AVERAGE(Projection_12M!B9:M9) -> 1637.5 | C7: =AVERAGE(B6,C6)*Assumptions!B21*Assumptions!B22 -> 6525 | D7: =AVERAGE(C6,D6)*Assumptions!B21*Assumptions!B22 -> 12375 | E7: Year average at 30% activation
A8: Advances in the year | B8: =Projection_12M!N10 -> 29476 | C8: =C7*Assumptions!B19*12 -> 117450 | D8: =D7*Assumptions!B19*12 -> 222750
A10: Gross revenue | B10: =Projection_12M!N13 -> 291812.4 | C10: =C8*Assumptions!B5 -> 1162755 | D10: =D8*Assumptions!B5 -> 2205225
A11: (-) Firm commission | B11: =Projection_12M!N14 -> -72953.1 | C11: =-C8*Assumptions!B7 -> -290688.75 | D11: =-D8*Assumptions!B7 -> -551306.25
A12: Net revenue | B12: =B10+B11 -> 218859.3 | C12: =C10+C11 -> 872066.25 | D12: =D10+D11 -> 1653918.8
A13: (-) Direct costs | B13: =Projection_12M!N23 -> -137358.16 | C13: =-C8*Assumptions!B14 -> -547317 | D13: =-D8*Assumptions!B14 -> -1038015
A14: Gross margin | B14: =B12+B13 -> 81501.14 | C14: =C12+C13 -> 324749.25 | D14: =D12+D13 -> 615903.75
A16: (-) Annual fixed costs | B16: =Projection_12M!N27 -> -140100 | C16: -360000 | D16: -540000 | E16: Expanded team: senior dev + 2 support + CS + mkt + legal
A17: EBITDA | B17: =B14+B16 -> -58598.86 | C17: =C14+C16 -> -35250.75 | D17: =D14+D16 -> 75903.75
A18: EBITDA margin | B18: =IFERROR(B17/B12,0) -> -0.26774672 | C18: =IFERROR(C17/C12,0) -> -0.040422101 | D18: =IFERROR(D17/D12,0) -> 0.045893276
A20: Capital contributions | B20: =Projection_12M!N33 -> 103000 | C20: 0 | D20: 0
A21: Annual cash flow | B21: =B17+B20 -> 44401.14 | C21: =C17+C20 -> -35250.75 | D21: =D17+D20 -> 75903.75
A22: Accumulated cash | B22: =B21 -> 44401.14 | C22: =B22+C21 -> 9150.39 | D22: =C22+D21 -> 85054.14

Sheet Financial_Analysis
A1: Financial Analysis — IRR, NPV, ROI, Break-even
A2: Investment viability metrics
A4: INITIAL INVESTMENT
A5: Founder's contribution | B5: =Assumptions!B50 -> 3000
A6: Angel investor contribution | B6: =Assumptions!B51 -> 100000
A7: Total investment | B7: =B5+B6 -> 103000
A9: CASH FLOWS FOR ANALYSIS
A10: Year | B10: Cash Flow | C10: Note | G10: Operational CF (no TV)
A11: 0 | B11: =-B7 -> -103000 | C11: Initial investment | F11: =B11 -> -103000 | G11: =B11 -> -103000
A12: 1 | B12: =Projection_36M!B17 -> -58598.86 | C12: EBITDA Year 1 | F12: =B12 -> -58598.86 | G12: =B12 -> -58598.86
A13: 2 | B13: =Projection_36M!C17 -> -35250.75 | C13: EBITDA Year 2 | F13: =B13 -> -35250.75 | G13: =B13 -> -35250.75
A14: 3 | B14: =Projection_36M!D17 -> 75903.75 | C14: EBITDA Year 3 | F14: =B16 -> 455422.5 | G14: =B14 -> 75903.75
A15: TV | B15: =B14*D15 -> 379518.75 | C15: Terminal value = 5x EBITDA Year 3 (conservative exit multiple) | D15: 5
A16: 3 + TV | B16: =B14+B15 -> 455422.5 | C16: Total flow in year 3
A18: VIABILITY METRICS
A19: NPV (Net Present Value) | B19: =B11+NPV(Assumptions!B52,B12,B13,B16) -> 118837.52 | C19: =Assumptions!B52 -> 0.15 | D19: Operational NPV (no TV) | E19: =B11+NPV(Assumptions!B52,B12,B13,B14) -> -130702.21
A20: IRR (Internal Rate of Return) | B20: =IRR(F11:F14,0.1) -> 0.4105972 | C20: p.a. | D20: Operational IRR (no TV) | E20: =IFERROR(IRR(G11:G14,0.1),"Does not recover in 3 years") -> Does not recover in 3 years
A21: Return on Investment (EBITDA Year 3 / Contribution) | B21: =B14/B7 -> 0.73692961
A22: Payback (years) | B22: =IF(B12+B13>=B7,2+IFERROR((B7-B12)/B13,0),IF(B12+B13+B14>=B7,2+(B7-B12-B13)/B14,IF(B12>=B7,1,">3 years"))) -> >3 years
A24: OPERATIONAL BREAK-EVEN
A25: Monthly fixed cost (expansion phase) | B25: =Assumptions!C46 -> 18500
A26: Gross margin per transaction | B26: =Assumptions!B15 -> 2.765
A27: Transactions/month at break-even | B27: =B25/B26 -> 6690.7776
A28: Active users at break-even | B28: =B27/Assumptions!B19 -> 4460.5184
A29: Firms in full operation at break-even | B29: =B28/(Assumptions!B21*Assumptions!B22) -> 9.9122631

Sheet Scenarios
A1: Scenario analysis
A2: Variation of key assumptions to test model sensitivity
A4: Assumption | B4: Pessimistic | C4: Base | D4: Optimistic | E4: Comment
A5: Active firms at end of Year 1 | B5: 5 | C5: 9 | D5: 14 | E5: Slower or faster acquisition than expected
A6: Activation rate at steady state | B6: 0.2 | C6: 0.3 | D6: 0.4 | E6: Real employee adoption of the product
A7: Employees per firm (average) | B7: 1200 | C7: 1500 | D7: 2000 | E7: Average size of firm portfolios
A8: Usage frequency per user/month | B8: 1 | C8: 1.5 | D8: 2 | E8: Real frequency after adoption
A9: Average ticket | B9: 180 | C9: 200 | D9: 250 | E9: Average amount advanced per transaction
A10: Average Year 1 ramp factor (derived from Projection_12M) | B10: =Projection_36M!B7/(C5*C7*C6) -> 0.40432099
A12: IMPACT ON RESULTS
A13: Metric | B13: Pessimistic | C13: Base | D13: Optimistic | E13: Optimistic/pessimistic spread
A14: Average active users (Year 1) | B14: =B5*B7*B6*$B$10 -> 485.18519 | C14: =C5*C7*C6*$B$10 -> 1637.5 | D14: =D5*D7*D6*$B$10 -> 4528.3951 | E14: =D14/B14 -> 9.3333333
A15: Annual gross revenue | B15: =B14*B8*12*Assumptions!B5 -> 57640 | C15: =C14*C8*12*Assumptions!B5 -> 291802.5 | D15: =D14*D8*12*Assumptions!B5 -> 1075946.7 | E15: =D15/B15 -> 18.666667
A16: Annual gross margin | B16: =B14*B8*12*Assumptions!B15 -> 16098.444 | C16: =C14*C8*12*Assumptions!B15 -> 81498.375 | D16: =D14*D8*12*Assumptions!B15 -> 300504.3 | E16: =D16/B16 -> 18.666667
A18: CONCLUSION
A19: Pessimistic scenario | B19: Break-even in ~24 months, requires additional contribution in Year 2
A20: Base scenario | B20: Break-even in 14-18 months, initial contribution sufficient
A21: Optimistic scenario | B21: Break-even in 10-12 months, positive cash generation already in Year 2
